2021-12-05 11:55:05,239 INFO: Microblog startup [in /home/jayesh/Desktop/myproj/flask_practice/Miguel_tut/main_app/__init__.py:33]
2021-12-05 11:55:25,671 ERROR: Exception on /register [POST] [in /home/jayesh/Desktop/myproj/flask_practice/Miguel_tut/my_env/lib/python3.8/site-packages/flask/app.py:1457]
Traceback (most recent call last):
  File "/home/jayesh/Desktop/myproj/flask_practice/Miguel_tut/my_env/lib/python3.8/site-packages/sqlalchemy/engine/base.py", line 1802, in _execute_context
    self.dialect.do_execute(
  File "/home/jayesh/Desktop/myproj/flask_practice/Miguel_tut/my_env/lib/python3.8/site-packages/sqlalchemy/engine/default.py", line 719, in do_execute
    cursor.execute(statement, parameters)
sqlite3.IntegrityError: UNIQUE constraint failed: user.username

The above exception was the direct cause of the following exception:

Traceback (most recent call last):
  File "/home/jayesh/Desktop/myproj/flask_practice/Miguel_tut/my_env/lib/python3.8/site-packages/flask/app.py", line 2073, in wsgi_app
    response = self.full_dispatch_request()
  File "/home/jayesh/Desktop/myproj/flask_practice/Miguel_tut/my_env/lib/python3.8/site-packages/flask/app.py", line 1518, in full_dispatch_request
    rv = self.handle_user_exception(e)
  File "/home/jayesh/Desktop/myproj/flask_practice/Miguel_tut/my_env/lib/python3.8/site-packages/flask/app.py", line 1516, in full_dispatch_request
    rv = self.dispatch_request()
  File "/home/jayesh/Desktop/myproj/flask_practice/Miguel_tut/my_env/lib/python3.8/site-packages/flask/app.py", line 1502, in dispatch_request
    return self.ensure_sync(self.view_functions[rule.endpoint])(**req.view_args)
  File "/home/jayesh/Desktop/myproj/flask_practice/Miguel_tut/main_app/routes.py", line 61, in register
    db.session.commit()
  File "<string>", line 2, in commit
  File "/home/jayesh/Desktop/myproj/flask_practice/Miguel_tut/my_env/lib/python3.8/site-packages/sqlalchemy/orm/session.py", line 1428, in commit
    self._transaction.commit(_to_root=self.future)
  File "/home/jayesh/Desktop/myproj/flask_practice/Miguel_tut/my_env/lib/python3.8/site-packages/sqlalchemy/orm/session.py", line 829, in commit
    self._prepare_impl()
  File "/home/jayesh/Desktop/myproj/flask_practice/Miguel_tut/my_env/lib/python3.8/site-packages/sqlalchemy/orm/session.py", line 808, in _prepare_impl
    self.session.flush()
  File "/home/jayesh/Desktop/myproj/flask_practice/Miguel_tut/my_env/lib/python3.8/site-packages/sqlalchemy/orm/session.py", line 3345, in flush
    self._flush(objects)
  File "/home/jayesh/Desktop/myproj/flask_practice/Miguel_tut/my_env/lib/python3.8/site-packages/sqlalchemy/orm/session.py", line 3485, in _flush
    transaction.rollback(_capture_exception=True)
  File "/home/jayesh/Desktop/myproj/flask_practice/Miguel_tut/my_env/lib/python3.8/site-packages/sqlalchemy/util/langhelpers.py", line 70, in __exit__
    compat.raise_(
  File "/home/jayesh/Desktop/myproj/flask_practice/Miguel_tut/my_env/lib/python3.8/site-packages/sqlalchemy/util/compat.py", line 207, in raise_
    raise exception
  File "/home/jayesh/Desktop/myproj/flask_practice/Miguel_tut/my_env/lib/python3.8/site-packages/sqlalchemy/orm/session.py", line 3445, in _flush
    flush_context.execute()
  File "/home/jayesh/Desktop/myproj/flask_practice/Miguel_tut/my_env/lib/python3.8/site-packages/sqlalchemy/orm/unitofwork.py", line 456, in execute
    rec.execute(self)
  File "/home/jayesh/Desktop/myproj/flask_practice/Miguel_tut/my_env/lib/python3.8/site-packages/sqlalchemy/orm/unitofwork.py", line 630, in execute
    util.preloaded.orm_persistence.save_obj(
  File "/home/jayesh/Desktop/myproj/flask_practice/Miguel_tut/my_env/lib/python3.8/site-packages/sqlalchemy/orm/persistence.py", line 244, in save_obj
    _emit_insert_statements(
  File "/home/jayesh/Desktop/myproj/flask_practice/Miguel_tut/my_env/lib/python3.8/site-packages/sqlalchemy/orm/persistence.py", line 1221, in _emit_insert_statements
    result = connection._execute_20(
  File "/home/jayesh/Desktop/myproj/flask_practice/Miguel_tut/my_env/lib/python3.8/site-packages/sqlalchemy/engine/base.py", line 1614, in _execute_20
    return meth(self, args_10style, kwargs_10style, execution_options)
  File "/home/jayesh/Desktop/myproj/flask_practice/Miguel_tut/my_env/lib/python3.8/site-packages/sqlalchemy/sql/elements.py", line 325, in _execute_on_connection
    return connection._execute_clauseelement(
  File "/home/jayesh/Desktop/myproj/flask_practice/Miguel_tut/my_env/lib/python3.8/site-packages/sqlalchemy/engine/base.py", line 1481, in _execute_clauseelement
    ret = self._execute_context(
  File "/home/jayesh/Desktop/myproj/flask_practice/Miguel_tut/my_env/lib/python3.8/site-packages/sqlalchemy/engine/base.py", line 1845, in _execute_context
    self._handle_dbapi_exception(
  File "/home/jayesh/Desktop/myproj/flask_practice/Miguel_tut/my_env/lib/python3.8/site-packages/sqlalchemy/engine/base.py", line 2026, in _handle_dbapi_exception
    util.raise_(
  File "/home/jayesh/Desktop/myproj/flask_practice/Miguel_tut/my_env/lib/python3.8/site-packages/sqlalchemy/util/compat.py", line 207, in raise_
    raise exception
  File "/home/jayesh/Desktop/myproj/flask_practice/Miguel_tut/my_env/lib/python3.8/site-packages/sqlalchemy/engine/base.py", line 1802, in _execute_context
    self.dialect.do_execute(
  File "/home/jayesh/Desktop/myproj/flask_practice/Miguel_tut/my_env/lib/python3.8/site-packages/sqlalchemy/engine/default.py", line 719, in do_execute
    cursor.execute(statement, parameters)
sqlalchemy.exc.IntegrityError: (sqlite3.IntegrityError) UNIQUE constraint failed: user.username
[SQL: INSERT INTO user (username, email, password_hash, about_me, last_seen) VALUES (?, ?, ?, ?, ?)]
[parameters: ('jaay', 'jaay@mail.com', 'pbkdf2:sha256:260000$fXzhVFNhyrVg9t7K$011850e07597fea4b78282bf1178cc8e7d6e9d4cd0a08a1c2e2135ca8c46077b', None, '2021-12-05 06:25:25.671629')]
(Background on this error at: https://sqlalche.me/e/14/gkpj)
2021-12-05 12:06:34,076 INFO: Microblog startup [in /home/jayesh/Desktop/myproj/flask_practice/Miguel_tut/main_app/__init__.py:37]
2021-12-05 12:06:46,329 INFO: Microblog startup [in /home/jayesh/Desktop/myproj/flask_practice/Miguel_tut/main_app/__init__.py:37]
2021-12-05 19:19:12,279 INFO: Microblog startup [in /home/jayesh/Desktop/myproj/flask_practice/Miguel_tut/main_app/__init__.py:37]
2021-12-05 19:19:20,444 INFO: Microblog startup [in /home/jayesh/Desktop/myproj/flask_practice/Miguel_tut/main_app/__init__.py:37]
2021-12-05 19:19:29,750 INFO: Microblog startup [in /home/jayesh/Desktop/myproj/flask_practice/Miguel_tut/main_app/__init__.py:37]
2021-12-05 19:19:52,071 INFO: Microblog startup [in /home/jayesh/Desktop/myproj/flask_practice/Miguel_tut/main_app/__init__.py:37]
2021-12-05 19:31:33,796 INFO: Microblog startup [in /home/jayesh/Desktop/myproj/flask_practice/Miguel_tut/main_app/__init__.py:37]
2021-12-05 19:31:51,587 ERROR: Exception on /user/jaay [GET] [in /home/jayesh/Desktop/myproj/flask_practice/Miguel_tut/my_env/lib/python3.8/site-packages/flask/app.py:1457]
Traceback (most recent call last):
  File "/home/jayesh/Desktop/myproj/flask_practice/Miguel_tut/my_env/lib/python3.8/site-packages/flask/app.py", line 2073, in wsgi_app
    response = self.full_dispatch_request()
  File "/home/jayesh/Desktop/myproj/flask_practice/Miguel_tut/my_env/lib/python3.8/site-packages/flask/app.py", line 1518, in full_dispatch_request
    rv = self.handle_user_exception(e)
  File "/home/jayesh/Desktop/myproj/flask_practice/Miguel_tut/my_env/lib/python3.8/site-packages/flask/app.py", line 1516, in full_dispatch_request
    rv = self.dispatch_request()
  File "/home/jayesh/Desktop/myproj/flask_practice/Miguel_tut/my_env/lib/python3.8/site-packages/flask/app.py", line 1502, in dispatch_request
    return self.ensure_sync(self.view_functions[rule.endpoint])(**req.view_args)
  File "/home/jayesh/Desktop/myproj/flask_practice/Miguel_tut/main_app/routes.py", line 80, in user
    return render_template("user.html", params=locals())
  File "/home/jayesh/Desktop/myproj/flask_practice/Miguel_tut/my_env/lib/python3.8/site-packages/flask/templating.py", line 147, in render_template
    return _render(
  File "/home/jayesh/Desktop/myproj/flask_practice/Miguel_tut/my_env/lib/python3.8/site-packages/flask/templating.py", line 128, in _render
    rv = template.render(context)
  File "/home/jayesh/Desktop/myproj/flask_practice/Miguel_tut/my_env/lib/python3.8/site-packages/jinja2/environment.py", line 1291, in render
    self.environment.handle_exception()
  File "/home/jayesh/Desktop/myproj/flask_practice/Miguel_tut/my_env/lib/python3.8/site-packages/jinja2/environment.py", line 925, in handle_exception
    raise rewrite_traceback_stack(source=source)
  File "/home/jayesh/Desktop/myproj/flask_practice/Miguel_tut/main_app/templates/user.html", line 1, in top-level template code
    {% extends "base.html" %}
  File "/home/jayesh/Desktop/myproj/flask_practice/Miguel_tut/main_app/templates/base.html", line 33, in top-level template code
    {% block content %}{% endblock %}
  File "/home/jayesh/Desktop/myproj/flask_practice/Miguel_tut/main_app/templates/user.html", line 8, in block 'content'
    <h1>User: {{ user.username }}</h1>
  File "/home/jayesh/Desktop/myproj/flask_practice/Miguel_tut/my_env/lib/python3.8/site-packages/jinja2/environment.py", line 474, in getattr
    return getattr(obj, attribute)
jinja2.exceptions.UndefinedError: 'user' is undefined
